2025-03-17 21:40:10,660 INFO    MainThread:78125 [wandb_setup.py:_flush():67] Current SDK version is 0.19.8
2025-03-17 21:40:10,660 INFO    MainThread:78125 [wandb_setup.py:_flush():67] Configure stats pid to 78125
2025-03-17 21:40:10,660 INFO    MainThread:78125 [wandb_setup.py:_flush():67] Loading settings from /Users/happy/.config/wandb/settings
2025-03-17 21:40:10,660 INFO    MainThread:78125 [wandb_setup.py:_flush():67] Loading settings from /Users/happy/Desktop/25-1-DS-Week-1-Assignment/wandb/settings
2025-03-17 21:40:10,660 INFO    MainThread:78125 [wandb_setup.py:_flush():67] Loading settings from environment variables
2025-03-17 21:40:10,660 INFO    MainThread:78125 [wandb_init.py:setup_run_log_directory():647] Logging user logs to /Users/happy/Desktop/25-1-DS-Week-1-Assignment/wandb/run-20250317_214010-ic3zdf2f/logs/debug.log
2025-03-17 21:40:10,660 INFO    MainThread:78125 [wandb_init.py:setup_run_log_directory():648] Logging internal logs to /Users/happy/Desktop/25-1-DS-Week-1-Assignment/wandb/run-20250317_214010-ic3zdf2f/logs/debug-internal.log
2025-03-17 21:40:10,660 INFO    MainThread:78125 [wandb_init.py:monkeypatch_ipython():599] configuring jupyter hooks <wandb.sdk.wandb_init._WandbInit object at 0x146a764d0>
2025-03-17 21:40:10,660 INFO    MainThread:78125 [wandb_init.py:init():761] calling init triggers
2025-03-17 21:40:10,661 INFO    MainThread:78125 [wandb_init.py:init():766] wandb.init called with sweep_config: {}
config: {'src_vocab_size': 100, 'tgt_vocab_size': 200, 'd_model': 32, 'n_heads': 4, 'd_ff': 64, 'num_encoder_layers': 6, 'num_decoder_layers': 6, 'dropout': 0.1, 'batch_size': 32, 'num_epochs': 50, 'learning_rate': 0.0001, '_wandb': {}}
2025-03-17 21:40:10,661 INFO    MainThread:78125 [wandb_init.py:init():784] starting backend
2025-03-17 21:40:10,661 INFO    MainThread:78125 [wandb_init.py:init():788] sending inform_init request
2025-03-17 21:40:10,677 INFO    MainThread:78125 [backend.py:_multiprocessing_setup():101] multiprocessing start_methods=spawn,fork,forkserver, using: spawn
2025-03-17 21:40:10,677 INFO    MainThread:78125 [wandb_init.py:init():798] backend started and connected
2025-03-17 21:40:10,680 INFO    MainThread:78125 [wandb_run.py:_label_probe_notebook():1204] probe notebook
2025-03-17 21:40:10,681 INFO    MainThread:78125 [wandb_init.py:init():891] updated telemetry
2025-03-17 21:40:10,681 INFO    MainThread:78125 [wandb_init.py:init():915] communicating run to backend with 90.0 second timeout
2025-03-17 21:40:11,093 INFO    MainThread:78125 [wandb_init.py:init():990] starting run threads in backend
2025-03-17 21:40:11,133 INFO    MainThread:78125 [wandb_run.py:_console_start():2375] atexit reg
2025-03-17 21:40:11,134 INFO    MainThread:78125 [wandb_run.py:_redirect():2227] redirect: wrap_raw
2025-03-17 21:40:11,134 INFO    MainThread:78125 [wandb_run.py:_redirect():2292] Wrapping output streams.
2025-03-17 21:40:11,134 INFO    MainThread:78125 [wandb_run.py:_redirect():2315] Redirects installed.
2025-03-17 21:40:11,135 INFO    MainThread:78125 [wandb_init.py:init():1032] run started, returning control to user process
2025-03-17 21:40:28,293 WARNING MsgRouterThr:78125 [router.py:message_loop():63] message_loop has been closed
Traceback (most recent call last):
  File "/Users/happy/miniconda3/envs/ds_homework/lib/python3.10/site-packages/wandb/sdk/interface/router_sock.py", line 27, in _read_message
    return self._sock_client.read_server_response(timeout=1)
  File "/Users/happy/miniconda3/envs/ds_homework/lib/python3.10/site-packages/wandb/sdk/lib/sock_client.py", line 235, in read_server_response
    data = self._read_packet_bytes(timeout=timeout)
  File "/Users/happy/miniconda3/envs/ds_homework/lib/python3.10/site-packages/wandb/sdk/lib/sock_client.py", line 220, in _read_packet_bytes
    raise SockClientClosedError
wandb.sdk.lib.sock_client.SockClientClosedError

The above exception was the direct cause of the following exception:

Traceback (most recent call last):
  File "/Users/happy/miniconda3/envs/ds_homework/lib/python3.10/site-packages/wandb/sdk/interface/router.py", line 56, in message_loop
    msg = self._read_message()
  File "/Users/happy/miniconda3/envs/ds_homework/lib/python3.10/site-packages/wandb/sdk/interface/router_sock.py", line 29, in _read_message
    raise MessageRouterClosedError from e
wandb.sdk.interface.router.MessageRouterClosedError
2025-03-17 21:40:28,296 INFO    MsgRouterThr:78125 [mailbox.py:close():129] Closing mailbox, abandoning 1 handles.
2025-03-17 21:40:28,407 INFO    MainThread:78125 [jupyter.py:save_ipynb():386] not saving jupyter notebook
2025-03-17 21:40:28,407 INFO    MainThread:78125 [wandb_init.py:_pause_backend():564] pausing backend
2025-03-17 21:40:33,697 INFO    MainThread:78125 [wandb_init.py:_resume_backend():569] resuming backend
2025-03-17 21:40:33,698 ERROR   MainThread:78125 [redirect.py:_on_write():661] error in stdout callback
Traceback (most recent call last):
  File "/Users/happy/miniconda3/envs/ds_homework/lib/python3.10/site-packages/IPython/core/events.py", line 82, in trigger
    func(*args, **kwargs)
  File "/Users/happy/miniconda3/envs/ds_homework/lib/python3.10/site-packages/wandb/sdk/wandb_init.py", line 570, in _resume_backend
    self.backend.interface.publish_resume()
  File "/Users/happy/miniconda3/envs/ds_homework/lib/python3.10/site-packages/wandb/sdk/interface/interface.py", line 777, in publish_resume
    self._publish_resume(resume)
  File "/Users/happy/miniconda3/envs/ds_homework/lib/python3.10/site-packages/wandb/sdk/interface/interface_shared.py", line 293, in _publish_resume
    self._publish(rec)
  File "/Users/happy/miniconda3/envs/ds_homework/lib/python3.10/site-packages/wandb/sdk/interface/interface_sock.py", line 39, in _publish
    self._sock_client.send_record_publish(record)
  File "/Users/happy/miniconda3/envs/ds_homework/lib/python3.10/site-packages/wandb/sdk/lib/sock_client.py", line 174, in send_record_publish
    self.send_server_request(server_req)
  File "/Users/happy/miniconda3/envs/ds_homework/lib/python3.10/site-packages/wandb/sdk/lib/sock_client.py", line 154, in send_server_request
    self._send_message(msg)
  File "/Users/happy/miniconda3/envs/ds_homework/lib/python3.10/site-packages/wandb/sdk/lib/sock_client.py", line 151, in _send_message
    self._sendall_with_error_handle(header + data)
  File "/Users/happy/miniconda3/envs/ds_homework/lib/python3.10/site-packages/wandb/sdk/lib/sock_client.py", line 130, in _sendall_with_error_handle
    sent = self._sock.send(data)
BrokenPipeError: [Errno 32] Broken pipe

During handling of the above exception, another exception occurred:

Traceback (most recent call last):
  File "/Users/happy/miniconda3/envs/ds_homework/lib/python3.10/site-packages/wandb/sdk/lib/redirect.py", line 659, in _on_write
    cb(written_data)
  File "/Users/happy/miniconda3/envs/ds_homework/lib/python3.10/site-packages/wandb/sdk/wandb_run.py", line 2296, in <lambda>
    lambda data: self._console_raw_callback("stdout", data),
  File "/Users/happy/miniconda3/envs/ds_homework/lib/python3.10/site-packages/wandb/sdk/wandb_run.py", line 401, in wrapper_fn
    return func(self, *args, **kwargs)
  File "/Users/happy/miniconda3/envs/ds_homework/lib/python3.10/site-packages/wandb/sdk/wandb_run.py", line 1444, in _console_raw_callback
    self._backend.interface.publish_output_raw(name, data)
  File "/Users/happy/miniconda3/envs/ds_homework/lib/python3.10/site-packages/wandb/sdk/interface/interface.py", line 761, in publish_output_raw
    self._publish_output_raw(o)
  File "/Users/happy/miniconda3/envs/ds_homework/lib/python3.10/site-packages/wandb/sdk/interface/interface_shared.py", line 38, in _publish_output_raw
    self._publish(rec)
  File "/Users/happy/miniconda3/envs/ds_homework/lib/python3.10/site-packages/wandb/sdk/interface/interface_sock.py", line 39, in _publish
    self._sock_client.send_record_publish(record)
  File "/Users/happy/miniconda3/envs/ds_homework/lib/python3.10/site-packages/wandb/sdk/lib/sock_client.py", line 174, in send_record_publish
    self.send_server_request(server_req)
  File "/Users/happy/miniconda3/envs/ds_homework/lib/python3.10/site-packages/wandb/sdk/lib/sock_client.py", line 154, in send_server_request
    self._send_message(msg)
  File "/Users/happy/miniconda3/envs/ds_homework/lib/python3.10/site-packages/wandb/sdk/lib/sock_client.py", line 151, in _send_message
    self._sendall_with_error_handle(header + data)
  File "/Users/happy/miniconda3/envs/ds_homework/lib/python3.10/site-packages/wandb/sdk/lib/sock_client.py", line 130, in _sendall_with_error_handle
    sent = self._sock.send(data)
BrokenPipeError: [Errno 32] Broken pipe
2025-03-17 21:40:33,700 ERROR   MainThread:78125 [redirect.py:_on_write():661] error in stdout callback
Traceback (most recent call last):
  File "/Users/happy/miniconda3/envs/ds_homework/lib/python3.10/site-packages/IPython/core/events.py", line 82, in trigger
    func(*args, **kwargs)
  File "/Users/happy/miniconda3/envs/ds_homework/lib/python3.10/site-packages/wandb/sdk/wandb_init.py", line 570, in _resume_backend
    self.backend.interface.publish_resume()
  File "/Users/happy/miniconda3/envs/ds_homework/lib/python3.10/site-packages/wandb/sdk/interface/interface.py", line 777, in publish_resume
    self._publish_resume(resume)
  File "/Users/happy/miniconda3/envs/ds_homework/lib/python3.10/site-packages/wandb/sdk/interface/interface_shared.py", line 293, in _publish_resume
    self._publish(rec)
  File "/Users/happy/miniconda3/envs/ds_homework/lib/python3.10/site-packages/wandb/sdk/interface/interface_sock.py", line 39, in _publish
    self._sock_client.send_record_publish(record)
  File "/Users/happy/miniconda3/envs/ds_homework/lib/python3.10/site-packages/wandb/sdk/lib/sock_client.py", line 174, in send_record_publish
    self.send_server_request(server_req)
  File "/Users/happy/miniconda3/envs/ds_homework/lib/python3.10/site-packages/wandb/sdk/lib/sock_client.py", line 154, in send_server_request
    self._send_message(msg)
  File "/Users/happy/miniconda3/envs/ds_homework/lib/python3.10/site-packages/wandb/sdk/lib/sock_client.py", line 151, in _send_message
    self._sendall_with_error_handle(header + data)
  File "/Users/happy/miniconda3/envs/ds_homework/lib/python3.10/site-packages/wandb/sdk/lib/sock_client.py", line 130, in _sendall_with_error_handle
    sent = self._sock.send(data)
BrokenPipeError: [Errno 32] Broken pipe

During handling of the above exception, another exception occurred:

Traceback (most recent call last):
  File "/Users/happy/miniconda3/envs/ds_homework/lib/python3.10/site-packages/wandb/sdk/lib/redirect.py", line 659, in _on_write
    cb(written_data)
  File "/Users/happy/miniconda3/envs/ds_homework/lib/python3.10/site-packages/wandb/sdk/wandb_run.py", line 2296, in <lambda>
    lambda data: self._console_raw_callback("stdout", data),
  File "/Users/happy/miniconda3/envs/ds_homework/lib/python3.10/site-packages/wandb/sdk/wandb_run.py", line 401, in wrapper_fn
    return func(self, *args, **kwargs)
  File "/Users/happy/miniconda3/envs/ds_homework/lib/python3.10/site-packages/wandb/sdk/wandb_run.py", line 1444, in _console_raw_callback
    self._backend.interface.publish_output_raw(name, data)
  File "/Users/happy/miniconda3/envs/ds_homework/lib/python3.10/site-packages/wandb/sdk/interface/interface.py", line 761, in publish_output_raw
    self._publish_output_raw(o)
  File "/Users/happy/miniconda3/envs/ds_homework/lib/python3.10/site-packages/wandb/sdk/interface/interface_shared.py", line 38, in _publish_output_raw
    self._publish(rec)
  File "/Users/happy/miniconda3/envs/ds_homework/lib/python3.10/site-packages/wandb/sdk/interface/interface_sock.py", line 39, in _publish
    self._sock_client.send_record_publish(record)
  File "/Users/happy/miniconda3/envs/ds_homework/lib/python3.10/site-packages/wandb/sdk/lib/sock_client.py", line 174, in send_record_publish
    self.send_server_request(server_req)
  File "/Users/happy/miniconda3/envs/ds_homework/lib/python3.10/site-packages/wandb/sdk/lib/sock_client.py", line 154, in send_server_request
    self._send_message(msg)
  File "/Users/happy/miniconda3/envs/ds_homework/lib/python3.10/site-packages/wandb/sdk/lib/sock_client.py", line 151, in _send_message
    self._sendall_with_error_handle(header + data)
  File "/Users/happy/miniconda3/envs/ds_homework/lib/python3.10/site-packages/wandb/sdk/lib/sock_client.py", line 130, in _sendall_with_error_handle
    sent = self._sock.send(data)
BrokenPipeError: [Errno 32] Broken pipe
2025-03-17 21:40:33,843 INFO    MainThread:78125 [wandb_init.py:setup_run_log_directory():647] Logging user logs to /Users/happy/Desktop/25-1-DS-Week-1-Assignment/wandb/run-20250317_214033-btgphol4/logs/debug.log
2025-03-17 21:40:33,843 INFO    MainThread:78125 [wandb_init.py:setup_run_log_directory():648] Logging internal logs to /Users/happy/Desktop/25-1-DS-Week-1-Assignment/wandb/run-20250317_214033-btgphol4/logs/debug-internal.log
2025-03-17 21:40:33,843 INFO    MainThread:78125 [wandb_init.py:init():761] calling init triggers
2025-03-17 21:40:33,843 INFO    MainThread:78125 [wandb_init.py:init():766] wandb.init called with sweep_config: {}
config: {'src_vocab_size': 100, 'tgt_vocab_size': 200, 'd_model': 32, 'n_heads': 4, 'd_ff': 64, 'num_encoder_layers': 6, 'num_decoder_layers': 6, 'dropout': 0.1, 'batch_size': 32, 'num_epochs': 50, 'learning_rate': 0.0001, '_wandb': {}}
2025-03-17 21:40:33,843 INFO    MainThread:78125 [wandb_init.py:init():776] wandb.init() called while a run is active
2025-03-17 21:40:33,843 ERROR   MainThread:78125 [wandb_init.py:init():1478] error in wandb.init()
Traceback (most recent call last):
  File "/Users/happy/miniconda3/envs/ds_homework/lib/python3.10/site-packages/wandb/sdk/wandb_init.py", line 1468, in init
    return wi.init(run_settings, run_config)
  File "/Users/happy/miniconda3/envs/ds_homework/lib/python3.10/site-packages/wandb/sdk/wandb_init.py", line 779, in init
    with telemetry.context() as tel:
  File "/Users/happy/miniconda3/envs/ds_homework/lib/python3.10/site-packages/wandb/sdk/lib/telemetry.py", line 42, in __exit__
    self._run._telemetry_callback(self._obj)
  File "/Users/happy/miniconda3/envs/ds_homework/lib/python3.10/site-packages/wandb/sdk/wandb_run.py", line 749, in _telemetry_callback
    self._telemetry_flush()
  File "/Users/happy/miniconda3/envs/ds_homework/lib/python3.10/site-packages/wandb/sdk/wandb_run.py", line 762, in _telemetry_flush
    self._backend.interface._publish_telemetry(self._telemetry_obj)
  File "/Users/happy/miniconda3/envs/ds_homework/lib/python3.10/site-packages/wandb/sdk/interface/interface_shared.py", line 60, in _publish_telemetry
    self._publish(rec)
  File "/Users/happy/miniconda3/envs/ds_homework/lib/python3.10/site-packages/wandb/sdk/interface/interface_sock.py", line 39, in _publish
    self._sock_client.send_record_publish(record)
  File "/Users/happy/miniconda3/envs/ds_homework/lib/python3.10/site-packages/wandb/sdk/lib/sock_client.py", line 174, in send_record_publish
    self.send_server_request(server_req)
  File "/Users/happy/miniconda3/envs/ds_homework/lib/python3.10/site-packages/wandb/sdk/lib/sock_client.py", line 154, in send_server_request
    self._send_message(msg)
  File "/Users/happy/miniconda3/envs/ds_homework/lib/python3.10/site-packages/wandb/sdk/lib/sock_client.py", line 151, in _send_message
    self._sendall_with_error_handle(header + data)
  File "/Users/happy/miniconda3/envs/ds_homework/lib/python3.10/site-packages/wandb/sdk/lib/sock_client.py", line 130, in _sendall_with_error_handle
    sent = self._sock.send(data)
BrokenPipeError: [Errno 32] Broken pipe
2025-03-17 21:40:33,989 INFO    MainThread:78125 [jupyter.py:save_ipynb():386] not saving jupyter notebook
2025-03-17 21:40:33,989 INFO    MainThread:78125 [wandb_init.py:_pause_backend():564] pausing backend
2025-03-17 21:40:33,989 ERROR   MainThread:78125 [redirect.py:_on_write():661] error in stdout callback
Traceback (most recent call last):
  File "/Users/happy/miniconda3/envs/ds_homework/lib/python3.10/site-packages/IPython/core/events.py", line 82, in trigger
    func(*args, **kwargs)
  File "/Users/happy/miniconda3/envs/ds_homework/lib/python3.10/site-packages/wandb/sdk/wandb_init.py", line 565, in _pause_backend
    self.backend.interface.publish_pause()
  File "/Users/happy/miniconda3/envs/ds_homework/lib/python3.10/site-packages/wandb/sdk/interface/interface.py", line 769, in publish_pause
    self._publish_pause(pause)
  File "/Users/happy/miniconda3/envs/ds_homework/lib/python3.10/site-packages/wandb/sdk/interface/interface_shared.py", line 289, in _publish_pause
    self._publish(rec)
  File "/Users/happy/miniconda3/envs/ds_homework/lib/python3.10/site-packages/wandb/sdk/interface/interface_sock.py", line 39, in _publish
    self._sock_client.send_record_publish(record)
  File "/Users/happy/miniconda3/envs/ds_homework/lib/python3.10/site-packages/wandb/sdk/lib/sock_client.py", line 174, in send_record_publish
    self.send_server_request(server_req)
  File "/Users/happy/miniconda3/envs/ds_homework/lib/python3.10/site-packages/wandb/sdk/lib/sock_client.py", line 154, in send_server_request
    self._send_message(msg)
  File "/Users/happy/miniconda3/envs/ds_homework/lib/python3.10/site-packages/wandb/sdk/lib/sock_client.py", line 151, in _send_message
    self._sendall_with_error_handle(header + data)
  File "/Users/happy/miniconda3/envs/ds_homework/lib/python3.10/site-packages/wandb/sdk/lib/sock_client.py", line 130, in _sendall_with_error_handle
    sent = self._sock.send(data)
BrokenPipeError: [Errno 32] Broken pipe

During handling of the above exception, another exception occurred:

Traceback (most recent call last):
  File "/Users/happy/miniconda3/envs/ds_homework/lib/python3.10/site-packages/wandb/sdk/lib/redirect.py", line 659, in _on_write
    cb(written_data)
  File "/Users/happy/miniconda3/envs/ds_homework/lib/python3.10/site-packages/wandb/sdk/wandb_run.py", line 2296, in <lambda>
    lambda data: self._console_raw_callback("stdout", data),
  File "/Users/happy/miniconda3/envs/ds_homework/lib/python3.10/site-packages/wandb/sdk/wandb_run.py", line 401, in wrapper_fn
    return func(self, *args, **kwargs)
  File "/Users/happy/miniconda3/envs/ds_homework/lib/python3.10/site-packages/wandb/sdk/wandb_run.py", line 1444, in _console_raw_callback
    self._backend.interface.publish_output_raw(name, data)
  File "/Users/happy/miniconda3/envs/ds_homework/lib/python3.10/site-packages/wandb/sdk/interface/interface.py", line 761, in publish_output_raw
    self._publish_output_raw(o)
  File "/Users/happy/miniconda3/envs/ds_homework/lib/python3.10/site-packages/wandb/sdk/interface/interface_shared.py", line 38, in _publish_output_raw
    self._publish(rec)
  File "/Users/happy/miniconda3/envs/ds_homework/lib/python3.10/site-packages/wandb/sdk/interface/interface_sock.py", line 39, in _publish
    self._sock_client.send_record_publish(record)
  File "/Users/happy/miniconda3/envs/ds_homework/lib/python3.10/site-packages/wandb/sdk/lib/sock_client.py", line 174, in send_record_publish
    self.send_server_request(server_req)
  File "/Users/happy/miniconda3/envs/ds_homework/lib/python3.10/site-packages/wandb/sdk/lib/sock_client.py", line 154, in send_server_request
    self._send_message(msg)
  File "/Users/happy/miniconda3/envs/ds_homework/lib/python3.10/site-packages/wandb/sdk/lib/sock_client.py", line 151, in _send_message
    self._sendall_with_error_handle(header + data)
  File "/Users/happy/miniconda3/envs/ds_homework/lib/python3.10/site-packages/wandb/sdk/lib/sock_client.py", line 130, in _sendall_with_error_handle
    sent = self._sock.send(data)
BrokenPipeError: [Errno 32] Broken pipe
2025-03-17 21:40:33,990 ERROR   MainThread:78125 [redirect.py:_on_write():661] error in stdout callback
Traceback (most recent call last):
  File "/Users/happy/miniconda3/envs/ds_homework/lib/python3.10/site-packages/IPython/core/events.py", line 82, in trigger
    func(*args, **kwargs)
  File "/Users/happy/miniconda3/envs/ds_homework/lib/python3.10/site-packages/wandb/sdk/wandb_init.py", line 565, in _pause_backend
    self.backend.interface.publish_pause()
  File "/Users/happy/miniconda3/envs/ds_homework/lib/python3.10/site-packages/wandb/sdk/interface/interface.py", line 769, in publish_pause
    self._publish_pause(pause)
  File "/Users/happy/miniconda3/envs/ds_homework/lib/python3.10/site-packages/wandb/sdk/interface/interface_shared.py", line 289, in _publish_pause
    self._publish(rec)
  File "/Users/happy/miniconda3/envs/ds_homework/lib/python3.10/site-packages/wandb/sdk/interface/interface_sock.py", line 39, in _publish
    self._sock_client.send_record_publish(record)
  File "/Users/happy/miniconda3/envs/ds_homework/lib/python3.10/site-packages/wandb/sdk/lib/sock_client.py", line 174, in send_record_publish
    self.send_server_request(server_req)
  File "/Users/happy/miniconda3/envs/ds_homework/lib/python3.10/site-packages/wandb/sdk/lib/sock_client.py", line 154, in send_server_request
    self._send_message(msg)
  File "/Users/happy/miniconda3/envs/ds_homework/lib/python3.10/site-packages/wandb/sdk/lib/sock_client.py", line 151, in _send_message
    self._sendall_with_error_handle(header + data)
  File "/Users/happy/miniconda3/envs/ds_homework/lib/python3.10/site-packages/wandb/sdk/lib/sock_client.py", line 130, in _sendall_with_error_handle
    sent = self._sock.send(data)
BrokenPipeError: [Errno 32] Broken pipe

During handling of the above exception, another exception occurred:

Traceback (most recent call last):
  File "/Users/happy/miniconda3/envs/ds_homework/lib/python3.10/site-packages/wandb/sdk/lib/redirect.py", line 659, in _on_write
    cb(written_data)
  File "/Users/happy/miniconda3/envs/ds_homework/lib/python3.10/site-packages/wandb/sdk/wandb_run.py", line 2296, in <lambda>
    lambda data: self._console_raw_callback("stdout", data),
  File "/Users/happy/miniconda3/envs/ds_homework/lib/python3.10/site-packages/wandb/sdk/wandb_run.py", line 401, in wrapper_fn
    return func(self, *args, **kwargs)
  File "/Users/happy/miniconda3/envs/ds_homework/lib/python3.10/site-packages/wandb/sdk/wandb_run.py", line 1444, in _console_raw_callback
    self._backend.interface.publish_output_raw(name, data)
  File "/Users/happy/miniconda3/envs/ds_homework/lib/python3.10/site-packages/wandb/sdk/interface/interface.py", line 761, in publish_output_raw
    self._publish_output_raw(o)
  File "/Users/happy/miniconda3/envs/ds_homework/lib/python3.10/site-packages/wandb/sdk/interface/interface_shared.py", line 38, in _publish_output_raw
    self._publish(rec)
  File "/Users/happy/miniconda3/envs/ds_homework/lib/python3.10/site-packages/wandb/sdk/interface/interface_sock.py", line 39, in _publish
    self._sock_client.send_record_publish(record)
  File "/Users/happy/miniconda3/envs/ds_homework/lib/python3.10/site-packages/wandb/sdk/lib/sock_client.py", line 174, in send_record_publish
    self.send_server_request(server_req)
  File "/Users/happy/miniconda3/envs/ds_homework/lib/python3.10/site-packages/wandb/sdk/lib/sock_client.py", line 154, in send_server_request
    self._send_message(msg)
  File "/Users/happy/miniconda3/envs/ds_homework/lib/python3.10/site-packages/wandb/sdk/lib/sock_client.py", line 151, in _send_message
    self._sendall_with_error_handle(header + data)
  File "/Users/happy/miniconda3/envs/ds_homework/lib/python3.10/site-packages/wandb/sdk/lib/sock_client.py", line 130, in _sendall_with_error_handle
    sent = self._sock.send(data)
BrokenPipeError: [Errno 32] Broken pipe
